unhandled exception during asyncio.run() shutdown
task: <Task finished name='Task-1' coro=<_run_app() done, defined at /usr/local/lib/python3.11/site-packages/aiohttp/web.py:289> exception=OSError(98, "error while attempting to bind on address ('172.17.0.2', 5050): address already in use")>
Traceback (most recent call last):
  File "/usr/local/lib/python3.11/site-packages/aiohttp/web.py", line 516, in run_app
    loop.run_until_complete(main_task)
  File "/usr/local/lib/python3.11/asyncio/base_events.py", line 653, in run_until_complete
    return future.result()
           ^^^^^^^^^^^^^^^
  File "/usr/local/lib/python3.11/site-packages/aiohttp/web.py", line 415, in _run_app
    await site.start()
  File "/usr/local/lib/python3.11/site-packages/aiohttp/web_runner.py", line 121, in start
    self._server = await loop.create_server(
                   ^^^^^^^^^^^^^^^^^^^^^^^^^
  File "/usr/local/lib/python3.11/asyncio/base_events.py", line 1525, in create_server
    raise OSError(err.errno, 'error while attempting '
OSError: [Errno 98] error while attempting to bind on address ('172.17.0.2', 5050): address already in use
Traceback (most recent call last):
  File "/opt/lulu/LuLu-ai-project/bot_lulu_main.py", line 58, in <module>
    raise error
  File "/opt/lulu/LuLu-ai-project/bot_lulu_main.py", line 56, in <module>
    web.run_app(APP, host="172.17.0.2", port=CONFIG.PORT)
  File "/usr/local/lib/python3.11/site-packages/aiohttp/web.py", line 516, in run_app
    loop.run_until_complete(main_task)
  File "/usr/local/lib/python3.11/asyncio/base_events.py", line 653, in run_until_complete
    return future.result()
           ^^^^^^^^^^^^^^^
  File "/usr/local/lib/python3.11/site-packages/aiohttp/web.py", line 415, in _run_app
    await site.start()
  File "/usr/local/lib/python3.11/site-packages/aiohttp/web_runner.py", line 121, in start
    self._server = await loop.create_server(
                   ^^^^^^^^^^^^^^^^^^^^^^^^^
  File "/usr/local/lib/python3.11/asyncio/base_events.py", line 1525, in create_server
    raise OSError(err.errno, 'error while attempting '
OSError: [Errno 98] error while attempting to bind on address ('172.17.0.2', 5050): address already in use
